<?xml version="1.0" encoding="utf-8"?>
<!-- =================================================================================== -->
<!-- |    This document was autogenerated by xacro from goat.urdf.xacro                | -->
<!-- |    EDITING THIS FILE BY HAND IS NOT RECOMMENDED                                 | -->
<!-- =================================================================================== -->
<robot name="goat" xmlns:xacro="http://www.ros.org/wiki/xacro">
  <!-- no GPU acceleration for us rn :-P -->
  <material name="black">
    <color rgba="0.0 0.0 0.0 1.0"/>
  </material>
  <material name="blue">
    <color rgba="0.0 0.0 0.8 1.0"/>
  </material>
  <material name="green">
    <color rgba="0.0 0.8 0.0 1.0"/>
  </material>
  <material name="grey">
    <color rgba="0.2 0.2 0.2 1.0"/>
  </material>
  <material name="orange">
    <color rgba="1.0 0.423529411765 0.0392156862745 1.0"/>
  </material>
  <material name="brown">
    <color rgba="0.870588235294 0.811764705882 0.764705882353 1.0"/>
  </material>
  <material name="red">
    <color rgba="0.8 0.0 0.0 1.0"/>
  </material>
  <material name="white">
    <color rgba="1.0 1.0 1.0 1.0"/>
  </material>
  <!--gazebo reference="left_wheel_hinge">
      <mu1 value="10000.0" />
      <mu2 value="10000.0" />
      <kp value="100000.0" />
      <kd value="0.00001" />
      <maxVel value="1.0" />
      <minDepth value="0.0001" />
  </gazebo>    
  <gazebo reference="right_wheel_hinge">
      <mu1 value="10000.0" />
      <mu2 value="10000.0" />
      <kp value="100000.0" />
      <kd value="0.00001" />
      <maxVel value="1.0" />
      <minDepth value="0.0001" />
  </gazebo-->
  <gazebo>
    <plugin filename="libgazebo_ros_diff_drive.so" name="differential_drive_controller">
      <legacyMode>false</legacyMode>
      <alwaysOn>true</alwaysOn>
      <updateRate>10</updateRate>
      <leftJoint>left_wheel_joint</leftJoint>
      <rightJoint>right_wheel_joint</rightJoint>
      <wheelSeparation>0.5844</wheelSeparation>
      <wheelDiameter>0.3178</wheelDiameter>
      <torque>10</torque>
      <commandTopic>cmd_vel</commandTopic>
      <odometryTopic>odom</odometryTopic>
      <odometryFrame>odom</odometryFrame>
      <robotBaseFrame>chassis</robotBaseFrame>
    </plugin>
  </gazebo>
  <gazebo reference="base_center">
    <material>Gazebo/Yellow</material>
  </gazebo>
  <gazebo reference="base_board">
    <material>Gazebo/Orange</material>
  </gazebo>
  <gazebo reference="left_wheel">
    <material>Gazebo/Blue</material>
  </gazebo>
  <gazebo reference="right_wheel">
    <material>Gazebo/Blue</material>
  </gazebo>
  <!-- define base footprint -->
  <link name="base_footprint"/>
  <!-- right between the two encoders  -->
  <link name="base_link">
    <inertial>
      <origin rpy="0 0 0" xyz="0 0 0.5"/>
      <mass value="1"/>
      <inertia ixx="100" ixy="0" ixz="0" iyy="100" iyz="0" izz="100"/>
    </inertial>
    <visual>
      <geometry>
        <box size="0.01 0.01 0.01"/>
      </geometry>
      <material name="black"/>
    </visual>
  </link>
  <!-- link base of the robot with the footprint -->
  <joint name="footprint_base_link" type="fixed">
    <parent link="base_footprint"/>
    <child link="base_link"/>
    <origin rpy="0 0 0" xyz="0 0 0.5"/>
  </joint>
  <!-- center of the robot, for convenience -->
  <link name="base_center">
    <inertial>
      <origin rpy="0 0 0" xyz="0 0 0.5"/>
      <mass value="1"/>
      <inertia ixx="100" ixy="0" ixz="0" iyy="100" iyz="0" izz="100"/>
    </inertial>
    <visual>
      <geometry>
        <!-- 20in x 18.7in x 12in -->
        <box size="0.508 0.475 0.305"/>
      </geometry>
      <material name="white"/>
    </visual>
    <origin xyz="0.2020 0 -0.1"/>
    <collision>
      <geometry>
        <box size="0.762 0.4572 0.3048"/>
      </geometry>
    </collision>
  </link>
  <joint name="base_center_joint" type="fixed">
    <parent link="base_link"/>
    <child link="base_center"/>
    <origin xyz="-0.2020 0 0.1"/>
  </joint>
  <link name="base_board">
    <visual>
      <geometry>
        <!-- 8in x 18in x 8in -->
        <box size="0.203 0.4572 0.203"/>
      </geometry>
      <material name="yellow"/>
    </visual>
  </link>
  <joint name="base_board_joint" type="fixed">
    <parent link="base_center"/>
    <child link="base_board"/>
    <origin xyz="-0.3556 0 0.07112"/>
  </joint>
  <!--back wheel joint-->
  <joint name="back_wheel_joint" type="continuous">
    <parent link="base_center"/>
    <child link="back_wheel"/>
    <origin rpy="0 0 0" xyz="0 0 -0.1156"/>
    <dynamics damping="1.0" friction="1.0"/>
  </joint>
  <link name="back_wheel">
    <visual>
      <geometry>
        <!--<cylinder length="0.1016" radius="0.1589"/> -->
        <sphere radius="0.1589"/>
      </geometry>
      <material name="black"/>
      <origin rpy="1.5708 0 0" xyz="-0.5 0 0"/>
    </visual>
    <collision>
      <geometry>
        <!-- <cylinder length="0.1016" radius="0.1589"/> -->
        <sphere radius="0.1589"/>
      </geometry>
      <origin rpy="1.5708 0 0" xyz="-0.5 0 0"/>
    </collision>
    <inertial>
      <origin rpy="0 0 0" xyz="0 0 0"/>
      <mass value="5"/>
      <inertia ixx=".1" ixy="0.0" ixz="0.0" iyy=".1" iyz="0.0" izz=".1"/>
    </inertial>
  </link>
  <link name="mid_frame">
    <visual>
      <geometry>
        <!-- 11.8in x 18in x 1.1in -->
        <box size="0.29972 0.4752 0.02794"/>
      </geometry>
      <material name="white"/>
    </visual>
  </link>
  <joint name="mid_frame_joint" type="fixed">
    <parent link="base_center"/>
    <child link="mid_frame"/>
    <origin xyz="-0.40386 0 -0.04318"/>
  </joint>
  <link name="bottom_frame">
    <visual>
      <geometry>
        <!-- 16in x 18in x 1.1in -->
        <box size="0.4064 0.4752 0.02794"/>
      </geometry>
      <material name="white"/>
    </visual>
  </link>
  <joint name="bottom_frame_joint" type="fixed">
    <parent link="base_center"/>
    <child link="bottom_frame"/>
    <origin xyz="-0.4572 0 -0.13716"/>
  </joint>
  <!-- position between two front wheels - encoders centered around this -->
  <link name="encoders">
    <visual>
      <geometry>
        <box size="0.03 0.03 0.03"/>
      </geometry>
      <material name="redish"/>
    </visual>
  </link>
  <joint name="encoders_joint" type="fixed">
    <parent link="base_link"/>
    <child link="encoders"/>
    <origin xyz="0 0 0"/>
  </joint>
  <!-- left wheel joint -->
  <joint name="left_wheel_joint" type="continuous">
    <parent link="base_center"/>
    <child link="left_wheel"/>
    <axis xyz="1 0 0"/>
    <origin rpy="0 0 1.5708" xyz="0.2 0.2922 -0.1"/>
    <limit effort="1000" velocity="100"/>
    <dynamics damping="1.0" friction="1.0"/>
  </joint>
  <link name="left_wheel">
    <visual>
      <geometry>
        <cylinder length="0.1016" radius="0.1589"/>
      </geometry>
      <material name="black"/>
      <origin rpy="0 1.5708 0" xyz="0 0 0"/>
    </visual>
    <collision>
      <geometry>
        <cylinder length="0.1016" radius="0.1589"/>
      </geometry>
      <origin rpy="0 1.5708 0" xyz="0 0 0"/>
    </collision>
    <inertial>
      <origin rpy="0 1.5708 0" xyz="0 0 0"/>
      <mass value="5"/>
      <inertia ixx="0.1" ixy="0.0" ixz="0.0" iyy="0.1" iyz="0.0" izz="0.1"/>
    </inertial>
  </link>
  <!-- right wheel joint -->
  <joint name="right_wheel_joint" type="continuous">
    <parent link="base_center"/>
    <child link="right_wheel"/>
    <axis xyz="1 0 0"/>
    <origin rpy="0 0 -1.5708" xyz="0.2 -0.2922 -0.1"/>
    <limit effort="1000" velocity="100"/>
    <dynamics damping="1.0" friction="1.0"/>
  </joint>
  <link name="right_wheel">
    <visual>
      <geometry>
        <cylinder length="0.1016" radius="0.1589"/>
      </geometry>
      <material name="black"/>
      <origin rpy="0 1.5708 0" xyz="0 0 0"/>
    </visual>
    <collision>
      <geometry>
        <cylinder length="0.1016" radius="0.1589"/>
      </geometry>
      <origin rpy="0 1.5708 0" xyz="0 0 0"/>
    </collision>
    <inertial>
      <origin rpy="0 1.5708 0" xyz="0 0 0"/>
      <mass value="5"/>
      <inertia ixx="0.1" ixy="0.0" ixz="0.0" iyy="0.1" iyz="0.0" izz="0.1"/>
    </inertial>
  </link>
  <link name="top_box">
    <visual>
      <geometry>
        <!-- 12in x 16in x 6.5in -->
        <box size="0.3048 0.4064 0.1651"/>
      </geometry>
      <material name="cyan"/>
    </visual>
  </link>
  <joint name="top_box_joint" type="fixed">
    <parent link="base_center"/>
    <child link="top_box"/>
    <origin xyz="0.0508 0 0.23495"/>
  </joint>
  <link name="front_post">
    <visual>
      <geometry>
        <box size="0.0233 0.0211 0.5112"/>
      </geometry>
      <material name="white"/>
    </visual>
  </link>
  <joint name="front_post_joint" type="fixed">
    <parent link="bottom_frame"/>
    <child link="front_post"/>
    <origin xyz="-0.1799 0 0.26957"/>
  </joint>
  <link name="imu">
    <visual>
      <geometry>
        <box size="0.0508 0.0508 0.025"/>
      </geometry>
      <material name="black"/>
    </visual>
  </link>
  <joint name="imu_joint" type="fixed">
    <parent link="top_box"/>
    <child link="imu"/>
    <origin rpy="0 0 3.14159" xyz="-0.12 0 0.0699"/>
  </joint>
  <link name="zed_center">
    <visual>
      <geometry>
        <box size="0.0381 0.1778 0.0381"/>
      </geometry>
      <material name="black"/>
    </visual>
  </link>
  <joint name="camera_joint" type="fixed">
    <parent link="base_center"/>
    <child link="zed_center"/>
    <origin xyz="0.23495 0 0.17145"/>
  </joint>
  <link name="gps">
    <visual>
      <geometry>
        <cylinder length="0.0127" radius="0.0254"/>
      </geometry>
      <material name="black"/>
    </visual>
  </link>
  <joint name="gps_joint" type="fixed">
    <parent link="front_post"/>
    <child link="gps"/>
    <origin xyz="0 0 0.26195"/>
  </joint>
  <!-- changed, original samples: 1875 -->
  <joint name="velodyne_base_mount_joint" type="fixed">
    <origin rpy="0 0 0" xyz="0 0 0.084"/>
    <parent link="top_box"/>
    <child link="velodyne_base_link"/>
  </joint>
  <link name="velodyne_base_link">
    <inertial>
      <mass value="0.83"/>
      <origin xyz="0 0 0.03585"/>
      <inertia ixx="0.000908059425" ixy="0" ixz="0" iyy="0.000908059425" iyz="0" izz="0.0011049624"/>
    </inertial>
    <visual>
      <geometry>
        <mesh filename="package://goat_description/velodyne/velodyne_description/meshes/VLP16_base_1.dae"/>
      </geometry>
    </visual>
    <visual>
      <geometry>
        <mesh filename="package://goat_description/velodyne/velodyne_description/meshes/VLP16_base_2.dae"/>
      </geometry>
    </visual>
    <collision>
      <origin rpy="0 0 0" xyz="0 0 0.03585"/>
      <geometry>
        <cylinder length="0.0717" radius="0.0516"/>
      </geometry>
    </collision>
  </link>
  <joint name="velodyne_base_scan_joint" type="fixed">
    <origin rpy="0 0 0" xyz="0 0 0.0377"/>
    <parent link="velodyne_base_link"/>
    <child link="velodyne"/>
  </joint>
  <link name="velodyne">
    <inertial>
      <mass value="0.01"/>
      <origin xyz="0 0 0"/>
      <inertia ixx="1e-7" ixy="0" ixz="0" iyy="1e-7" iyz="0" izz="1e-7"/>
    </inertial>
    <visual>
      <origin xyz="0 0 -0.0377"/>
      <geometry>
        <mesh filename="package://goat_description/velodyne/velodyne_description/meshes/VLP16_scan.dae"/>
      </geometry>
    </visual>
  </link>
  <!-- Gazebo requires the velodyne_gazebo_plugins package -->
  <gazebo reference="velodyne">
    <sensor name="velodyne-VLP16" type="ray">
      <pose>0 0 0 0 0 0</pose>
      <visualize>false</visualize>
      <update_rate>10</update_rate>
      <ray>
        <scan>
          <horizontal>
            <samples>250</samples>
            <resolution>1</resolution>
            <min_angle>-3.14159265359</min_angle>
            <max_angle>3.14159265359</max_angle>
          </horizontal>
          <vertical>
            <samples>16</samples>
            <resolution>1</resolution>
            <min_angle>-0.261799387799</min_angle>
            <max_angle> 0.261799387799</max_angle>
          </vertical>
        </scan>
        <range>
          <min>0.3</min>
          <max>131.0</max>
          <resolution>0.001</resolution>
        </range>
        <noise>
          <type>gaussian</type>
          <mean>0.0</mean>
          <stddev>0.0</stddev>
        </noise>
      </ray>
      <plugin filename="libgazebo_ros_velodyne_laser.so" name="gazebo_ros_laser_controller">
        <topicName>/velodyne_points</topicName>
        <frameName>velodyne</frameName>
        <min_range>0.9</min_range>
        <max_range>130.0</max_range>
        <gaussianNoise>0.008</gaussianNoise>
      </plugin>
    </sensor>
  </gazebo>
  <!-- any idea what this does? it looks important -->
  <gazebo>
    <plugin filename="libgazebo_ros_control.so" name="gazebo_ros_control">
      <robotNamespace>/</robotNamespace>
    </plugin>
  </gazebo>
</robot>
